Workbook
Name SlicerCache_Table_1_Col_1: #N/A

Sheet Echelle de maturité
A1: Niveaux de Maturité | B1: Signification | C1: Libéllé | D1: Code couleur
A2: 1 | B2: Une conscience insuffisante des risques cyber pesant sur l'organisation. Pas ou peu de mesures spécifiques mises en oeuvre en matière de cybersécurité. | C2: 1 - Insuffisant
A3: 2 | B3: Une prise de conscience de l'existence de risques cyber pour l'organisation et une volonté de mettre en place des premières mesures cyber pertinentes. | C3: 2 - Émergent
A4: 3 | B4: Une conscience partagée des risques cyber pour l'organisation et la volonté de formaliser un plan d'action cyber complet tout en ajustant les moyens en conséquence. | C4: 3 - Intermédiaire
A5: 4 | B5: Une cartographie précise de ses risques cyber pour l'organisation, un plan d'action cyber approfondi et des moyens humains et budgétaires dédiés. | C5: 4 - Confirmé
A6: 5 | B6: Des objectifs de réduction des risques cyber intégrés à la stratégie de l'organisation. Des moyens humains, budgétaires conséquents, un plan d'action cyber exhaustif, adapté aux menaces stratégiques. | C6: 5 - Optimal
A7: NA | B7: Le critère ou l'exigence évalué n'est pas pertinent au regard des activités, du périmètre technique ou du cadre réglementaire de l'organisation. | C7: Non applicable
A32: DORA (Digital Operational Resilience Act, 2022) est un règlement européen visant à renforcer la résilience opérationnelle numérique du secteur financier. | B32: ISO 27001 (2005, révision 2022) est une norme internationale définissant les exigences pour la mise en place d'un système de management de la sécurité de l'information (SMSI).
A33: NIS2 (Network and Information Security, 2022) est une directive européenne qui élargit les exigences de cybersécurité à de nouveaux secteurs essentiels. | B33: ISO 27002 (2005, révision 2022) est une norme internationale qui fournit un ensemble de bonnes pratiques et de contrôles de sécurité de l'information.
A34: PSSI (Politique de Sécurité des Systèmes d'Information) définit le plan d'action et les règles de sécurité à appliquer au sein d'une organisation. | B34: ISO 27005 (2008, révision 2022) est une norme internationale qui fournit des lignes directrices pour la gestion des risques liés à la sécurité de l'information.
A35: GRC (Gouvernance, Risques et Conformité) est une approche intégrée permettant d'aligner la stratégie sur les objectifs tout en gérant les risques. | B35: MEHARI (Méthode Harmonisée d'Analyse de Risques, 1996) est une méthode globale d'évaluation et de management des risques liés à la sécurité de l'information.
A36: ANSSI (Agence Nationale de la Sécurité des Systèmes d'Information, 2009) est l'autorité française chargée de sécuriser le développement du numérique.
A37: CIS Controls (Center for Internet Security, 2008) est un ensemble de bonnes pratiques et de mesures défensives pour atténuer les cyberattaques courantes.

Sheet Guide dhygiène informatique ANS
A3: Chapitres | B3: ID | C3: Règle de bonnes pratiques | D3: Description de la règle | E3: Description intégrale | F3: Type d'actifs | G3: Preuves attendues | H3: Niveau de maturité | I3: Description du niveau | K3: Chapitres (Tri)
A4: SENSIBILISER ET FORMER | B4: 1 | C4: Former les équipes opérationnelles à la sécurité des systèmes d’information | D4: Les équipes opérationnelles disposant d'accès privilégiés doivent être formées à la sécurité des systèmes d'information dès leur prise de fonction. Ces formations doivent être renouvelées régulièrement et adaptées aux responsabilités de chaque métier afin de limiter les risques liés aux erreurs humaines et aux mauvaises pratiques. | E4: Voir règle | F4: Identités et accès, Systèmes d’exploitation, Réseaux, Logiciels | G4: Politique ou plan de formation SSI, registre des formations réalisées, attestations de participation, supports de formation, clauses de formation SSI dans les contrats de prestation | H4: 2 - Émergent | I4: {=IF(H4="", "", XLOOKUP(H4, 'Echelle de maturité'!$C$2:$C$7, 'Echelle de maturité'!$B$2:$B$7, ""))} -> Une prise de conscience de l'existence de risques cyber pour l'organisation et une volonté de mettre en place des premières mesures cyber pertinentes. | K4: =IFERROR(__xludf.DUMMYFUNCTION("ARRAYFORMULA(LET(filled, SCAN("""", A4:A45, LAMBDA(acc, v, IF(v="""", acc, v))), IF(filled="""","""", TEXT(MATCH(filled, UNIQUE(FILTER(A4:A45, A4:A45<>"""")), 0), ""00"") & "" - "" & filled)))"),"01 - SENSIBILISER ET FORMER") -> 01 - SENSIBILISER ET FORMER
B5: 2 | C5: Sensibiliser les utilisateurs aux bonnes pratiques élémentaires de sécurité informatique | D5: Tous les utilisateurs doivent être sensibilisés dès leur arrivée aux enjeux de sécurité et aux règles de bon usage du système d’information. Ces actions doivent être régulières et adaptées afin d’ancrer les bonnes pratiques et réduire les risques liés aux comportements humains. | E5: Voir règle | F5: Identités et accès, Matériels, Systèmes d’exploitation | G5: Programme de sensibilisation SSI, supports de communication (emails, intranet, affiches), comptes-rendus de sessions, registre des campagnes de sensibilisation, charte informatique signée (option renforcée) | H5: 5 - Optimal | I5: {=IF(H5="", "", XLOOKUP(H5, 'Echelle de maturité'!$C$2:$C$7, 'Echelle de maturité'!$B$2:$B$7, ""))} -> Des objectifs de réduction des risques cyber intégrés à la stratégie de l'organisation. Des moyens humains, budgétaires conséquents, un plan d'action cyber exhaustif, adapté aux menaces stratégiques. | K5: =IFERROR(__xludf.DUMMYFUNCTION("""COMPUTED_VALUE"""),"01 - SENSIBILISER ET FORMER") -> 01 - SENSIBILISER ET FORMER
B6: 3 | C6: Maîtriser les risques de l’infogérance | D6: L’externalisation du SI ou des données doit être précédée d’une analyse de risques SSI afin d’identifier les exigences de sécurité à imposer au prestataire. Ces exigences doivent être formalisées contractuellement pour garantir la maîtrise, la réversibilité et le maintien du niveau de sécurité. | E6: Voir règle | F6: Données, Services, Applications, Infrastructures | G6: Analyse de risques SSI, cahier des charges de sécurité, contrats avec clauses SSI, plan d’assurance sécurité (PAS), procédures de réversibilité et de restitution des données | H6: 5 - Optimal | I6: {=IF(H6="", "", XLOOKUP(H6, 'Echelle de maturité'!$C$2:$C$7, 'Echelle de maturité'!$B$2:$B$7, ""))} -> Des objectifs de réduction des risques cyber intégrés à la stratégie de l'organisation. Des moyens humains, budgétaires conséquents, un plan d'action cyber exhaustif, adapté aux menaces stratégiques. | K6: =IFERROR(__xludf.DUMMYFUNCTION("""COMPUTED_VALUE"""),"01 - SENSIBILISER ET FORMER") -> 01 - SENSIBILISER ET FORMER
A7: CONNAÎTRE LE SYSTÈME D’INFORMATION | B7: 4 | C7: Identifier les informations et serveurs les plus sensibles et maintenir un schéma du réseau | D7: Les données sensibles doivent être identifiées et localisées dans le système d’information afin de déterminer les actifs critiques associés. Une cartographie à jour du SI doit permettre de visualiser les flux, les zones réseau et les composants hébergeant ces données | E7: Voir règle | F7: Données, Matériels, Réseaux, Systèmes d’exploitation | G7: Registre des données sensibles, cartographie réseau à jour, schéma d’architecture SI, inventaire des actifs critiques, documentation des flux et interconnexions | H7: 3 - Intermédiaire | I7: {=IF(H7="", "", XLOOKUP(H7, 'Echelle de maturité'!$C$2:$C$7, 'Echelle de maturité'!$B$2:$B$7, ""))} -> Une conscience partagée des risques cyber pour l'organisation et la volonté de formaliser un plan d'action cyber complet tout en ajustant les moyens en conséquence. | K7: =IFERROR(__xludf.DUMMYFUNCTION("""COMPUTED_VALUE"""),"02 - CONNAÎTRE LE SYSTÈME D’INFORMATION") -> 02 - CONNAÎTRE LE SYSTÈME D’INFORMATION
B8: 5 | C8: Disposer d’un inventaire exhaustif des comptes privilégiés et le maintenir à jour | D8: Les comptes disposant de droits élevés doivent être inventoriés et maintenus à jour afin de limiter les risques d’abus ou de compromission. Une revue régulière des droits permet de supprimer les accès obsolètes et de garantir la maîtrise des privilèges. | E8: Voir règle | F8: Identités et accès, Systèmes d’exploitation, Applications, Données | G8: Inventaire des comptes à privilèges, registre des comptes de service et administrateurs, procédures de revue périodique des droits, comptes-rendus de revues d’habilitation, règles de nomenclature des comptes | H8: Non Applicable | I8: {=IF(H8="", "", XLOOKUP(H8, 'Echelle de maturité'!$C$2:$C$7, 'Echelle de maturité'!$B$2:$B$7, ""))} -> Le critère ou l'exigence évalué n'est pas pertinent au regard des activités, du périmètre technique ou du cadre réglementaire de l'organisation. | K8: =IFERROR(__xludf.DUMMYFUNCTION("""COMPUTED_VALUE"""),"02 - CONNAÎTRE LE SYSTÈME D’INFORMATION") -> 02 - CONNAÎTRE LE SYSTÈME D’INFORMATION
B9: 6 | C9: Organiser les procédures d’arrivée, de départ et de changement de fonction des utilisateurs | D9: Les droits d’accès doivent être attribués, modifiés et supprimés en fonction des mouvements de personnel (arrivées, départs, changements de poste). Les procédures associées doivent garantir la révocation immédiate des accès lors d’un départ ou d’une évolution de fonction. | E9: Voir règle | F9: Identités et accès, Applications, Services, Matériels, Données | G9: Procédures RH et SSI de gestion des arrivées/départs/mobilité, tickets ou workflows d’onboarding/offboarding, preuves de désactivation de comptes, registres d’attribution/restitution des équipements et badges, matrices d’habilitation mises à jour | H9: 1 - Insuffisant | I9: {=IF(H9="", "", XLOOKUP(H9, 'Echelle de maturité'!$C$2:$C$7, 'Echelle de maturité'!$B$2:$B$7, ""))} -> Une conscience insuffisante des risques cyber pesant sur l'organisation. Pas ou peu de mesures spécifiques mises en oeuvre en matière de cybersécurité. | K9: =IFERROR(__xludf.DUMMYFUNCTION("""COMPUTED_VALUE"""),"02 - CONNAÎTRE LE SYSTÈME D’INFORMATION") -> 02 - CONNAÎTRE LE SYSTÈME D’INFORMATION
B10: 7 | C10: Autoriser la connexion au réseau de l’entité aux seuls équipements maîtrisés | D10: Seuls les équipements maîtrisés par l’entité doivent être autorisés à se connecter aux réseaux internes afin de réduire les risques d’intrusion et de compromission. Les équipements personnels ou visiteurs doivent être isolés via des réseaux dédiés ou des mesures de contrôle adaptées. | E10: Voir règle | F10: Matériels, Réseaux, Services | G10: Politique d’usage des équipements (BYOD), configuration des réseaux Wi-Fi (SSID invités/entreprise), règles de filtrage réseau, documentation NAC (ex : 802.1X), schéma d’architecture réseau | H10: 5 - Optimal | I10: {=IF(H10="", "", XLOOKUP(H10, 'Echelle de maturité'!$C$2:$C$7, 'Echelle de maturité'!$B$2:$B$7, ""))} -> Des objectifs de réduction des risques cyber intégrés à la stratégie de l'organisation. Des moyens humains, budgétaires conséquents, un plan d'action cyber exhaustif, adapté aux menaces stratégiques. | K10: =IFERROR(__xludf.DUMMYFUNCTION("""COMPUTED_VALUE"""),"02 - CONNAÎTRE LE SYSTÈME D’INFORMATION") -> 02 - CONNAÎTRE LE SYSTÈME D’INFORMATION
A11: AUTHENTIFIER ET CONTROLER LES ACCÈS | B11: 8 | C11: Identifier nommément chaque personne accédant au système et distinguer les rôles utilisateur/administrateur | D11: Les accès au système d’information doivent être réalisés au moyen de comptes nominatifs afin de garantir la traçabilité des actions. Les administrateurs doivent disposer d’un compte dédié à l’administration, distinct de leur compte utilisateur courant, et utilisé exclusivement pour les tâches d’administration. | E11: Voir règle | F11: Identités et accès, Logiciels, Services | G11: Politique de gestion des comptes, inventaire des comptes utilisateurs, administrateurs et de service, configuration des annuaires d'authentification, procédures d'administration, journaux de connexion et de journalisation des comptes (niveau renforcé) | H11: 4 - Confirmé | I11: {=IF(H11="", "", XLOOKUP(H11, 'Echelle de maturité'!$C$2:$C$7, 'Echelle de maturité'!$B$2:$B$7, ""))} -> Une cartographie précise de ses risques cyber pour l'organisation, un plan d'action cyber approfondi et des moyens humains et budgétaires dédiés. | K11: =IFERROR(__xludf.DUMMYFUNCTION("""COMPUTED_VALUE"""),"03 - AUTHENTIFIER ET CONTROLER LES ACCÈS") -> 03 - AUTHENTIFIER ET CONTROLER LES ACCÈS
B12: 9 | C12: Attribuer les bons droits sur les ressources sensibles du système d’information | D12: Les ressources contenant des informations sensibles doivent être identifiées et leur accès strictement limité aux utilisateurs autorisés. Les droits d'accès doivent être régulièrement revus afin de garantir leur adéquation avec les besoins réels et d'éviter toute exposition non maîtrisée des données. | E12: Voir règle | F12: Données, Applications, Services, Stockage | G12: Inventaire des ressources sensibles, matrices d'habilitation, listes de contrôle d'accès (ACL), procédures de gestion des droits, rapports de revue des habilitations, configuration des partages et bases de données | H12: 2 - Émergent | I12: {=IF(H12="", "", XLOOKUP(H12, 'Echelle de maturité'!$C$2:$C$7, 'Echelle de maturité'!$B$2:$B$7, ""))} -> Une prise de conscience de l'existence de risques cyber pour l'organisation et une volonté de mettre en place des premières mesures cyber pertinentes. | K12: =IFERROR(__xludf.DUMMYFUNCTION("""COMPUTED_VALUE"""),"03 - AUTHENTIFIER ET CONTROLER LES ACCÈS") -> 03 - AUTHENTIFIER ET CONTROLER LES ACCÈS
B13: 10 | C13: Définir et vérifier des règles de choix et de dimensionnement des mots de passe | D13: Les utilisateurs doivent appliquer des règles de création et d’utilisation de mots de passe garantissant un niveau de sécurité adapté. Des mécanismes techniques doivent compléter la sensibilisation afin de prévenir l’utilisation de mots de passe faibles ou compromis. | E13: Voir règle | F13: Identités et accès, Applications, Services | G13: Politique de mots de passe, configuration des règles de complexité et de verrouillage des comptes, rapports d’audit de robustesse des mots de passe, supports de sensibilisation, paramètres d’authentification des systèmes | H13: 4 - Confirmé | I13: {=IF(H13="", "", XLOOKUP(H13, 'Echelle de maturité'!$C$2:$C$7, 'Echelle de maturité'!$B$2:$B$7, ""))} -> Une cartographie précise de ses risques cyber pour l'organisation, un plan d'action cyber approfondi et des moyens humains et budgétaires dédiés. | K13: =IFERROR(__xludf.DUMMYFUNCTION("""COMPUTED_VALUE"""),"03 - AUTHENTIFIER ET CONTROLER LES ACCÈS") -> 03 - AUTHENTIFIER ET CONTROLER LES ACCÈS
B14: 11 | C14: Protéger les mots de passe stockés sur les systèmes | D14: Les mots de passe ne doivent pas être stockés sous des formes non sécurisées (fichiers, notes, navigateur, e-mail). Ils doivent être protégés via des solutions dédiées garantissant leur chiffrement et leur confinement. | E14: Voir règle | F14: Identités et accès, Logiciels | G14: Politique de gestion des mots de passe, déploiement d’un coffre-fort de mots de passe, configuration des outils de gestion des identifiants, recommandations de sécurité utilisateur, audits de configuration des navigateurs et postes | H14: 1 - Insuffisant | I14: {=IF(H14="", "", XLOOKUP(H14, 'Echelle de maturité'!$C$2:$C$7, 'Echelle de maturité'!$B$2:$B$7, ""))} -> Une conscience insuffisante des risques cyber pesant sur l'organisation. Pas ou peu de mesures spécifiques mises en oeuvre en matière de cybersécurité. | K14: =IFERROR(__xludf.DUMMYFUNCTION("""COMPUTED_VALUE"""),"03 - AUTHENTIFIER ET CONTROLER LES ACCÈS") -> 03 - AUTHENTIFIER ET CONTROLER LES ACCÈS
B15: 12 | C15: Changer les éléments d’authentification par défaut sur les équipements et services | D15: Les identifiants et mots de passe par défaut des systèmes et équipements doivent être modifiés dès leur installation. Ils doivent être remplacés par des secrets conformes aux règles de sécurité afin de limiter les risques de compromission initiale. | E15: Voir règle | F15: Matériels, Logiciels, Réseaux, Identités et accès | G15: Procédures d’installation et de durcissement, configurations des équipements, politique de gestion des secrets, inventaire des comptes par défaut supprimés ou modifiés, preuves de changement des identifiants initiaux | H15: Non Applicable | I15: {=IF(H15="", "", XLOOKUP(H15, 'Echelle de maturité'!$C$2:$C$7, 'Echelle de maturité'!$B$2:$B$7, ""))} -> Le critère ou l'exigence évalué n'est pas pertinent au regard des activités, du périmètre technique ou du cadre réglementaire de l'organisation. | K15: =IFERROR(__xludf.DUMMYFUNCTION("""COMPUTED_VALUE"""),"03 - AUTHENTIFIER ET CONTROLER LES ACCÈS") -> 03 - AUTHENTIFIER ET CONTROLER LES ACCÈS
B16: 13 | C16: Privilégier lorsque c’est possible une authentification forte | D16: L’accès aux systèmes doit reposer sur une authentification forte combinant au moins deux facteurs distincts. Cette approche réduit significativement le risque de compromission lié au vol ou à la faiblesse d’un seul facteur d’authentification. | E16: Voir règle | F16: Identités et accès, Applications, Services | G16: Politique d’authentification, configuration MFA des systèmes, rapports de déploiement MFA, preuves d’activation sur les applications critiques, documentation des méthodes d’authentification utilisées (OTP, cartes à puce, etc.) | H16: 3 - Intermédiaire | I16: {=IF(H16="", "", XLOOKUP(H16, 'Echelle de maturité'!$C$2:$C$7, 'Echelle de maturité'!$B$2:$B$7, ""))} -> Une conscience partagée des risques cyber pour l'organisation et la volonté de formaliser un plan d'action cyber complet tout en ajustant les moyens en conséquence. | K16: =IFERROR(__xludf.DUMMYFUNCTION("""COMPUTED_VALUE"""),"03 - AUTHENTIFIER ET CONTROLER LES ACCÈS") -> 03 - AUTHENTIFIER ET CONTROLER LES ACCÈS
A17: SÉCURISER LES POSTES | B17: 14 | C17: Mettre en place un niveau de sécurité minimal sur l’ensemble du parc informatique | D17: L’ensemble du parc informatique doit appliquer un niveau minimal de sécurité incluant la limitation des logiciels, la protection locale et le chiffrement des données. Les systèmes doivent être configurés pour réduire la surface d’attaque et isoler les environnements non conformes si nécessaire. | E17: Voir règle | F17: Matériels, Logiciels, Systèmes d’exploitation, Données | G17: Politique de durcissement des postes/serveurs, configurations antivirus et pare-feu locaux, paramétrage des postes (désactivation autorun, restriction logiciels), preuves de chiffrement des disques, procédures d’isolement des postes non conformes | H17: 5 - Optimal | I17: {=IF(H17="", "", XLOOKUP(H17, 'Echelle de maturité'!$C$2:$C$7, 'Echelle de maturité'!$B$2:$B$7, ""))} -> Des objectifs de réduction des risques cyber intégrés à la stratégie de l'organisation. Des moyens humains, budgétaires conséquents, un plan d'action cyber exhaustif, adapté aux menaces stratégiques. | K17: =IFERROR(__xludf.DUMMYFUNCTION("""COMPUTED_VALUE"""),"04 - SÉCURISER LES POSTES") -> 04 - SÉCURISER LES POSTES
B18: 15 | C18: Se protéger des menaces relatives à l’utilisation de supports amovibles | D18: L’usage des supports amovibles doit être encadré afin de limiter les risques de propagation de malware et de fuite de données. Leur utilisation doit être maîtrisée, et les périphériques non fiables doivent être interdits ou strictement contrôlés avant usage. | E18: Voir règle | F18: Matériels, Logiciels, Données | G18: Politique d’usage des supports amovibles, configurations de contrôle (blocage/exécution, antivirus), règles de sécurité des postes, procédures de mise au rebut/destruction sécurisée, journaux ou outils de contrôle des périphériques USB | H18: 5 - Optimal | I18: {=IF(H18="", "", XLOOKUP(H18, 'Echelle de maturité'!$C$2:$C$7, 'Echelle de maturité'!$B$2:$B$7, ""))} -> Des objectifs de réduction des risques cyber intégrés à la stratégie de l'organisation. Des moyens humains, budgétaires conséquents, un plan d'action cyber exhaustif, adapté aux menaces stratégiques. | K18: =IFERROR(__xludf.DUMMYFUNCTION("""COMPUTED_VALUE"""),"04 - SÉCURISER LES POSTES") -> 04 - SÉCURISER LES POSTES
B19: 16 | C19: Utiliser un outil de gestion centralisée afin d’homogénéiser les politiques de sécurité | D19: Les politiques de sécurité doivent être homogènes et appliquées de manière centralisée sur l’ensemble du parc informatique. Une gestion centralisée permet d’assurer la cohérence des configurations et d’accélérer l’application de mesures correctives en cas d’incident. | E19: Voir règle | F19: Matériels, Logiciels, Systèmes d’exploitation, Réseaux | G19: Architecture de gestion centralisée (ex. AD, MDM, GPO), configuration des politiques de sécurité appliquées, inventaire des équipements gérés, documentation des politiques de durcissement, procédures de déploiement et de mise à jour centralisée | H19: Non Applicable | I19: {=IF(H19="", "", XLOOKUP(H19, 'Echelle de maturité'!$C$2:$C$7, 'Echelle de maturité'!$B$2:$B$7, ""))} -> Le critère ou l'exigence évalué n'est pas pertinent au regard des activités, du périmètre technique ou du cadre réglementaire de l'organisation. | K19: =IFERROR(__xludf.DUMMYFUNCTION("""COMPUTED_VALUE"""),"04 - SÉCURISER LES POSTES") -> 04 - SÉCURISER LES POSTES
B20: 17 | C20: Activer et configurer le parefeu local des postes de travail | D20: Les postes de travail doivent disposer d’un pare-feu local activé afin de limiter les communications non autorisées et réduire les risques de propagation latérale. Une politique de filtrage adaptée permet de restreindre les flux inutiles et de protéger les systèmes contre les accès non souhaités. | E20: Voir règle | F20: Matériels, Systèmes d’exploitation, Réseaux | G20: Configuration des pare-feu locaux (Windows/Linux), politiques de filtrage appliquées, documentation des règles de sécurité réseau sur postes, éventuellement journaux de blocage des flux, procédures de durcissement des postes | H20: Non Applicable | I20: {=IF(H20="", "", XLOOKUP(H20, 'Echelle de maturité'!$C$2:$C$7, 'Echelle de maturité'!$B$2:$B$7, ""))} -> Le critère ou l'exigence évalué n'est pas pertinent au regard des activités, du périmètre technique ou du cadre réglementaire de l'organisation. | K20: =IFERROR(__xludf.DUMMYFUNCTION("""COMPUTED_VALUE"""),"04 - SÉCURISER LES POSTES") -> 04 - SÉCURISER LES POSTES
B21: 18 | C21: Chiffrer les données sensibles transmises par voie Internet | D21: Les données sensibles doivent être chiffrées avant toute transmission ou stockage sur des services externes non maîtrisés. Les secrets nécessaires au déchiffrement doivent être transmis via un canal distinct et de confiance. | E21: Voir règle | F21: Données, Logiciels, Services | G21: Politique de chiffrement des données, configuration des outils de chiffrement (email, cloud, fichiers), procédures de gestion des clés et secrets, preuves d’utilisation de solutions de chiffrement, recommandations utilisateurs | H21: Non Applicable | I21: {=IF(H21="", "", XLOOKUP(H21, 'Echelle de maturité'!$C$2:$C$7, 'Echelle de maturité'!$B$2:$B$7, ""))} -> Le critère ou l'exigence évalué n'est pas pertinent au regard des activités, du périmètre technique ou du cadre réglementaire de l'organisation. | K21: =IFERROR(__xludf.DUMMYFUNCTION("""COMPUTED_VALUE"""),"04 - SÉCURISER LES POSTES") -> 04 - SÉCURISER LES POSTES
A22: SÉCURISER LE RÉSEAU | B22: 19 | C22: Segmenter le réseau et mettre en place un cloisonnement entre ces zones | D22: Le réseau doit être segmenté en zones homogènes selon les niveaux de criticité et les usages afin de limiter les possibilités de déplacement latéral en cas de compromission. Des mécanismes de filtrage doivent contrôler les communications entre ces zones. | E22: Voir règle | F22: Réseaux, Infrastructures, Matériels | G22: Schéma d’architecture réseau, plan de segmentation (VLAN / sous-réseaux), règles de filtrage inter-zones (pare-feu), documentation d’architecture sécurité réseau, configuration des équipements réseau | H22: 2 - Émergent | I22: {=IF(H22="", "", XLOOKUP(H22, 'Echelle de maturité'!$C$2:$C$7, 'Echelle de maturité'!$B$2:$B$7, ""))} -> Une prise de conscience de l'existence de risques cyber pour l'organisation et une volonté de mettre en place des premières mesures cyber pertinentes. | K22: =IFERROR(__xludf.DUMMYFUNCTION("""COMPUTED_VALUE"""),"05 - SÉCURISER LE RÉSEAU") -> 05 - SÉCURISER LE RÉSEAU
B23: 20 | C23: S’assurer de la sécurité des réseaux d’accès Wi-Fi et de la séparation des usages | D23: Les réseaux Wi-Fi doivent être sécurisés par des mécanismes de chiffrement robustes et une authentification adaptée afin de limiter les risques d’intrusion. Les accès Wi-Fi doivent être segmentés selon les usages pour éviter tout accès non autorisé au système d’information interne. | E23: Voir règle | F23: Réseaux, Matériels, Systèmes d’exploitation | G23: Configuration des points d’accès Wi-Fi (WPA2/WPA3, AES), schéma de segmentation Wi-Fi (SSID/VLAN), règles de filtrage réseau, documentation d’authentification (certificats ou équivalent), configuration d’administration sécurisée des équipements Wi-Fi | H23: 4 - Confirmé | I23: {=IF(H23="", "", XLOOKUP(H23, 'Echelle de maturité'!$C$2:$C$7, 'Echelle de maturité'!$B$2:$B$7, ""))} -> Une cartographie précise de ses risques cyber pour l'organisation, un plan d'action cyber approfondi et des moyens humains et budgétaires dédiés. | K23: =IFERROR(__xludf.DUMMYFUNCTION("""COMPUTED_VALUE"""),"05 - SÉCURISER LE RÉSEAU") -> 05 - SÉCURISER LE RÉSEAU
B24: 21 | C24: Utiliser des protocoles réseaux sécurisés dès qu’ils existent | D24: Les communications doivent utiliser des protocoles sécurisés intégrant des mécanismes de chiffrement et d’intégrité dès que possible. Les protocoles non sécurisés doivent être remplacés par leurs équivalents sécurisés afin de protéger les échanges de données. | E24: Voir règle | F24: Réseaux, Services, Logiciels | G24: Configuration des services réseau (HTTPS, SSH, SMTPS, etc.), désactivation des protocoles non sécurisés (HTTP, Telnet, etc.), règles de configuration des serveurs et équipements réseau, scans de sécurité ou rapports d’audit des protocoles actifs | H24: Non Applicable | I24: {=IF(H24="", "", XLOOKUP(H24, 'Echelle de maturité'!$C$2:$C$7, 'Echelle de maturité'!$B$2:$B$7, ""))} -> Le critère ou l'exigence évalué n'est pas pertinent au regard des activités, du périmètre technique ou du cadre réglementaire de l'organisation. | K24: =IFERROR(__xludf.DUMMYFUNCTION("""COMPUTED_VALUE"""),"05 - SÉCURISER LE RÉSEAU") -> 05 - SÉCURISER LE RÉSEAU
B25: 22 | C25: Mettre en place une passerelle d’accès sécurisé à Internet | D25: Les accès Internet doivent transiter via une passerelle sécurisée intégrant filtrage et proxy afin de contrôler et journaliser les flux. Les postes utilisateurs ne doivent pas disposer d’un accès direct à Internet pour limiter les risques de compromission. | E25: Voir règle | F25: Réseaux, Services, Matériels | G25: Architecture de passerelle Internet, configuration du pare-feu et du proxy, règles de filtrage web, journaux de proxy, procédures d’administration et de maintien en conditions de sécurité, configuration DNS des postes | H25: 3 - Intermédiaire | I25: {=IF(H25="", "", XLOOKUP(H25, 'Echelle de maturité'!$C$2:$C$7, 'Echelle de maturité'!$B$2:$B$7, ""))} -> Une conscience partagée des risques cyber pour l'organisation et la volonté de formaliser un plan d'action cyber complet tout en ajustant les moyens en conséquence. | K25: =IFERROR(__xludf.DUMMYFUNCTION("""COMPUTED_VALUE"""),"05 - SÉCURISER LE RÉSEAU") -> 05 - SÉCURISER LE RÉSEAU
B26: 23 | C26: Cloisonner les services visibles depuis Internet du reste du système d’information | D26: Les services exposés sur Internet doivent être hébergés dans une infrastructure dédiée et isolée du reste du système d’information. Les flux entrants doivent être filtrés et contrôlés via des mécanismes de sécurité adaptés, notamment des reverse proxy. | E26: Voir règle | F26: Réseaux, Infrastructures, Services, Matériels | G26: Schéma d’architecture d’hébergement (DMZ), configuration des reverse proxy, règles de filtrage réseau, documentation de segmentation des environnements, inventaire des services exposés, procédures d’administration et de sécurisation des infrastructures | H26: 1 - Insuffisant | I26: {=IF(H26="", "", XLOOKUP(H26, 'Echelle de maturité'!$C$2:$C$7, 'Echelle de maturité'!$B$2:$B$7, ""))} -> Une conscience insuffisante des risques cyber pesant sur l'organisation. Pas ou peu de mesures spécifiques mises en oeuvre en matière de cybersécurité. | K26: =IFERROR(__xludf.DUMMYFUNCTION("""COMPUTED_VALUE"""),"05 - SÉCURISER LE RÉSEAU") -> 05 - SÉCURISER LE RÉSEAU
B27: 24 | C27: Protéger sa messagerie professionnelle | D27: La messagerie doit être protégée contre les menaces (malwares, phishing, fraude) via des mécanismes techniques et organisationnels adaptés. Les échanges doivent être sécurisés et les usages à risque (redirection externe, ouverture de contenus non vérifiés) encadrés. | E27: Voir règle | F27: Services, Réseaux, Logiciels, Données | G27: Configuration de la passerelle de messagerie, solution antivirus/anti-malware mail, activation TLS, politiques de sécurité messagerie, configuration anti-spam, enregistrements DNS (SPF, DKIM, DMARC), procédures de sensibilisation et règles d’usage | H27: 2 - Émergent | I27: {=IF(H27="", "", XLOOKUP(H27, 'Echelle de maturité'!$C$2:$C$7, 'Echelle de maturité'!$B$2:$B$7, ""))} -> Une prise de conscience de l'existence de risques cyber pour l'organisation et une volonté de mettre en place des premières mesures cyber pertinentes. | K27: =IFERROR(__xludf.DUMMYFUNCTION("""COMPUTED_VALUE"""),"05 - SÉCURISER LE RÉSEAU") -> 05 - SÉCURISER LE RÉSEAU
B28: 25 | C28: Sécuriser les interconnexions réseau dédiées avec les partenaires | D28: Les interconnexions avec des partenaires doivent être encadrées par des tunnels sécurisés et un filtrage strict des flux. Les échanges doivent être limités au strict nécessaire opérationnel afin de réduire la surface d’exposition. | E28: Voir règle | F28: Réseaux, Services, Infrastructures | G28: Schémas d’interconnexion, configuration VPN/IPsec, règles de pare-feu, matrice des flux autorisés, documentation de filtrage dédié, éventuellement configuration IDS/IPS | H28: 2 - Émergent | I28: {=IF(H28="", "", XLOOKUP(H28, 'Echelle de maturité'!$C$2:$C$7, 'Echelle de maturité'!$B$2:$B$7, ""))} -> Une prise de conscience de l'existence de risques cyber pour l'organisation et une volonté de mettre en place des premières mesures cyber pertinentes. | K28: =IFERROR(__xludf.DUMMYFUNCTION("""COMPUTED_VALUE"""),"05 - SÉCURISER LE RÉSEAU") -> 05 - SÉCURISER LE RÉSEAU
B29: 26 | C29: Contrôler et protéger l’accès aux salles serveurs et aux locaux techniques | D29: Les accès aux locaux techniques doivent être strictement contrôlés afin de limiter les intrusions physiques et les accès non autorisés aux systèmes. Les points d’accès réseau en zones accessibles doivent être maîtrisés ou désactivés pour éviter toute connexion non autorisée. | E29: Voir règle | F29: Matériels, Réseaux, Infrastructures | G29: Contrôle d’accès aux locaux (badges/serrures), journaux de contrôle d’accès physique, politique de gestion des accès physiques, inventaire des prises réseau actives/inactives, procédures de gestion des accès et revues périodiques des habilitations physiques | H29: 1 - Insuffisant | I29: {=IF(H29="", "", XLOOKUP(H29, 'Echelle de maturité'!$C$2:$C$7, 'Echelle de maturité'!$B$2:$B$7, ""))} -> Une conscience insuffisante des risques cyber pesant sur l'organisation. Pas ou peu de mesures spécifiques mises en oeuvre en matière de cybersécurité. | K29: =IFERROR(__xludf.DUMMYFUNCTION("""COMPUTED_VALUE"""),"05 - SÉCURISER LE RÉSEAU") -> 05 - SÉCURISER LE RÉSEAU
A30: SÉCURISER L’ADMINISTRATION | B30: 27 | C30: Interdire l’accès à Internet depuis les postes ou serveurs utilisés pour l’administration du système d’information | D30: Les environnements d’administration doivent être isolés d’Internet afin de réduire les risques d’exposition aux attaques. Les usages nécessitant Internet doivent être réalisés depuis un environnement distinct ou contrôlé pour éviter toute compromission des accès privilégiés. | E30: Voir règle | F30: Matériels, Systèmes d’exploitation, Réseaux, Logiciels | G30: Architecture des postes d’administration, règles de segmentation réseau, configuration des accès Internet (blocage ou isolation), documentation des environnements séparés (bureautique vs admin), procédures de transfert sécurisé de mises à jour | H30: 3 - Intermédiaire | I30: {=IF(H30="", "", XLOOKUP(H30, 'Echelle de maturité'!$C$2:$C$7, 'Echelle de maturité'!$B$2:$B$7, ""))} -> Une conscience partagée des risques cyber pour l'organisation et la volonté de formaliser un plan d'action cyber complet tout en ajustant les moyens en conséquence. | K30: =IFERROR(__xludf.DUMMYFUNCTION("""COMPUTED_VALUE"""),"06 - SÉCURISER L’ADMINISTRATION") -> 06 - SÉCURISER L’ADMINISTRATION
B31: 28 | C31: Utiliser un réseau dédié et cloisonné pour l’administration du système d’information | D31: Le réseau d’administration doit être isolé des autres réseaux afin de limiter les risques de compromission par rebond. Les flux d’administration doivent être strictement séparés et protégés par des mécanismes de cloisonnement adaptés. | E31: Voir règle | F31: Réseaux, Infrastructures, Matériels | G31: Schéma d’architecture réseau, configuration VLAN ou IPsec, règles de segmentation réseau, documentation du réseau d’administration, règles de filtrage inter-réseaux | H31: 3 - Intermédiaire | I31: {=IF(H31="", "", XLOOKUP(H31, 'Echelle de maturité'!$C$2:$C$7, 'Echelle de maturité'!$B$2:$B$7, ""))} -> Une conscience partagée des risques cyber pour l'organisation et la volonté de formaliser un plan d'action cyber complet tout en ajustant les moyens en conséquence. | K31: =IFERROR(__xludf.DUMMYFUNCTION("""COMPUTED_VALUE"""),"06 - SÉCURISER L’ADMINISTRATION") -> 06 - SÉCURISER L’ADMINISTRATION
B32: 29 | C32: Limiter au strict besoin opérationnel les droits d’administration sur les postes de travail | D32: Les utilisateurs ne doivent pas disposer de droits d’administration sur leurs postes de travail afin de limiter les risques d’exécution de logiciels malveillants et de modifications système non maîtrisées. Les élévations de privilèges doivent rester exceptionnelles, tracées et temporaires. | E32: Voir règle | F32: Matériels, Systèmes d’exploitation, Logiciels | G32: Politique de gestion des droits utilisateurs, configuration des postes (droits standards), inventaire des comptes locaux administrateurs, procédures de délégation temporaire de privilèges, journaux d’audit des élévations de droits | H32: Non Applicable | I32: {=IF(H32="", "", XLOOKUP(H32, 'Echelle de maturité'!$C$2:$C$7, 'Echelle de maturité'!$B$2:$B$7, ""))} -> Le critère ou l'exigence évalué n'est pas pertinent au regard des activités, du périmètre technique ou du cadre réglementaire de l'organisation. | K32: =IFERROR(__xludf.DUMMYFUNCTION("""COMPUTED_VALUE"""),"06 - SÉCURISER L’ADMINISTRATION") -> 06 - SÉCURISER L’ADMINISTRATION
A33: GÉRER LE NOMADISME | B33: 30 | C33: Prendre des mesures de sécurisation physique des terminaux nomades | D33: Les terminaux nomades doivent être protégés contre la perte, le vol et les accès non autorisés car ils peuvent contenir des données sensibles. Des mesures de protection physique et logique doivent être mises en place pour réduire leur exposition aux risques. | E33: Voir règle | F33: Matériels, Données, Systèmes d’exploitation | G33: Politique de sécurité des terminaux nomades, activation du chiffrement des disques, déploiement de filtres de confidentialité écran, procédures de gestion des pertes/vols, documentation sur l’authentification forte ou supports matériels complémentaires | H33: 2 - Émergent | I33: {=IF(H33="", "", XLOOKUP(H33, 'Echelle de maturité'!$C$2:$C$7, 'Echelle de maturité'!$B$2:$B$7, ""))} -> Une prise de conscience de l'existence de risques cyber pour l'organisation et une volonté de mettre en place des premières mesures cyber pertinentes. | K33: =IFERROR(__xludf.DUMMYFUNCTION("""COMPUTED_VALUE"""),"07 - GÉRER LE NOMADISME") -> 07 - GÉRER LE NOMADISME
B34: 31 | C34: Chiffrer les données sensibles, en particulier sur le matériel potentiellement perdable | D34: Les données stockées sur les terminaux et supports nomades doivent être chiffrées afin de protéger leur confidentialité en cas de perte ou de vol. L’accès aux données doit être conditionné à un secret robuste et unique. | E34: Voir règle | F34: Données, Matériels, Systèmes d’exploitation | G34: Politique de chiffrement des supports nomades, configuration du chiffrement de disque (ex. BitLocker, LUKS), procédures de gestion des clés de chiffrement, vérification de l’activation du chiffrement sur les équipements | H34: 3 - Intermédiaire | I34: {=IF(H34="", "", XLOOKUP(H34, 'Echelle de maturité'!$C$2:$C$7, 'Echelle de maturité'!$B$2:$B$7, ""))} -> Une conscience partagée des risques cyber pour l'organisation et la volonté de formaliser un plan d'action cyber complet tout en ajustant les moyens en conséquence. | K34: =IFERROR(__xludf.DUMMYFUNCTION("""COMPUTED_VALUE"""),"07 - GÉRER LE NOMADISME") -> 07 - GÉRER LE NOMADISME
B35: 32 | C35: Sécuriser la connexion réseau des postes utilisés en situation de nomadisme | D35: Les connexions distantes depuis des équipements nomades doivent transiter via un tunnel VPN sécurisé afin de protéger les échanges avec le système d’information. Le trafic doit être encapsulé dans ce tunnel pour éviter toute exposition directe sur Internet. | E35: Voir règle | F35: Réseaux, Systèmes d’exploitation, Services, Identités et accès | G35: Configuration de la solution VPN (IPsec/SSL), politiques de connexion distante, règles de routage forcé (full tunnel), documentation de la passerelle VPN, configuration d’authentification des accès distants | H35: 4 - Confirmé | I35: {=IF(H35="", "", XLOOKUP(H35, 'Echelle de maturité'!$C$2:$C$7, 'Echelle de maturité'!$B$2:$B$7, ""))} -> Une cartographie précise de ses risques cyber pour l'organisation, un plan d'action cyber approfondi et des moyens humains et budgétaires dédiés. | K35: =IFERROR(__xludf.DUMMYFUNCTION("""COMPUTED_VALUE"""),"07 - GÉRER LE NOMADISME") -> 07 - GÉRER LE NOMADISME
B36: 33 | C36: Adopter des politiques de sécurité dédiées aux terminaux mobiles | D36: Les terminaux mobiles utilisés en contexte professionnel doivent être sécurisés et gérés de manière homogène afin de réduire les risques liés à la compromission ou à la fuite de données. L’usage personnel et professionnel doit être séparé autant que possible. | E36: Voir règle | F36: Matériels, Systèmes d’exploitation, Applications, Données | G36: Politique de gestion des terminaux mobiles (MDM), configuration des politiques de sécurité (verrouillage, restrictions applications), inventaire des équipements mobiles, règles de séparation des usages, procédures de configuration initiale des appareils | H36: 5 - Optimal | I36: {=IF(H36="", "", XLOOKUP(H36, 'Echelle de maturité'!$C$2:$C$7, 'Echelle de maturité'!$B$2:$B$7, ""))} -> Des objectifs de réduction des risques cyber intégrés à la stratégie de l'organisation. Des moyens humains, budgétaires conséquents, un plan d'action cyber exhaustif, adapté aux menaces stratégiques. | K36: =IFERROR(__xludf.DUMMYFUNCTION("""COMPUTED_VALUE"""),"07 - GÉRER LE NOMADISME") -> 07 - GÉRER LE NOMADISME
A37: MAINTENIR LE SYSTÈME D’INFORMATION À JOUR | B37: 34 | C37: Définir une politique de mise à jour des composants du système d’information | D37: Les vulnérabilités doivent être corrigées via l’application régulière des correctifs de sécurité publiés par les éditeurs. Une politique de mise à jour structurée doit garantir l’identification, la qualification et le déploiement des correctifs dans des délais maîtrisés. | E37: Voir règle | F37: Logiciels, Systèmes d’exploitation, Matériels, Réseaux | G37: Politique de gestion des correctifs, inventaire des composants du SI, procédures de patch management, rapports de déploiement des mises à jour, outils de gestion des mises à jour (WSUS, équivalent), liste des systèmes obsolètes isolés | H37: 2 - Émergent | I37: {=IF(H37="", "", XLOOKUP(H37, 'Echelle de maturité'!$C$2:$C$7, 'Echelle de maturité'!$B$2:$B$7, ""))} -> Une prise de conscience de l'existence de risques cyber pour l'organisation et une volonté de mettre en place des premières mesures cyber pertinentes. | K37: =IFERROR(__xludf.DUMMYFUNCTION("""COMPUTED_VALUE"""),"08 - MAINTENIR LE SYSTÈME D’INFORMATION À JOUR") -> 08 - MAINTENIR LE SYSTÈME D’INFORMATION À JOUR
B38: 35 | C38: Anticiper la fin de la maintenance des logiciels et systèmes et limiter les adhérences logicielles | D38: Les systèmes et logiciels doivent être maintenus à jour et remplacés avant leur fin de support afin de limiter les vulnérabilités exploitables. Une stratégie d’anticipation de l’obsolescence doit être mise en place pour assurer la continuité de sécurité. | E38: Voir règle | F38: Logiciels, Systèmes d’exploitation, Matériels, Infrastructures | G38: Inventaire des logiciels et systèmes, suivi des versions et dates de fin de support (EOL/EOS), stratégie de gestion de l’obsolescence, plan de migration ou de remplacement, procédures de mise à jour et de migration, documentation de tests de non-régression | H38: 5 - Optimal | I38: {=IF(H38="", "", XLOOKUP(H38, 'Echelle de maturité'!$C$2:$C$7, 'Echelle de maturité'!$B$2:$B$7, ""))} -> Des objectifs de réduction des risques cyber intégrés à la stratégie de l'organisation. Des moyens humains, budgétaires conséquents, un plan d'action cyber exhaustif, adapté aux menaces stratégiques. | K38: =IFERROR(__xludf.DUMMYFUNCTION("""COMPUTED_VALUE"""),"08 - MAINTENIR LE SYSTÈME D’INFORMATION À JOUR") -> 08 - MAINTENIR LE SYSTÈME D’INFORMATION À JOUR
A39: SUPERVISER, AUDITER, RÉAGIR | B39: 36 | C39: Activer et configurer les journaux des composants les plus importants | D39: Les composants critiques du système d’information doivent générer des journaux exploitables permettant de détecter les incidents et tentatives d’intrusion. Les événements de sécurité doivent être conservés et synchronisés dans le temps pour permettre leur analyse et leur corrélation. | E39: Voir règle | F39: Réseaux, Logiciels, Systèmes d’exploitation, Services, Matériels | G39: Politique de journalisation, configuration des logs (serveurs, applications, pare-feu), règles de rétention des journaux, configuration NTP, preuve de centralisation des logs (SIEM ou équivalent), exemples de journaux collectés | H39: 2 - Émergent | I39: {=IF(H39="", "", XLOOKUP(H39, 'Echelle de maturité'!$C$2:$C$7, 'Echelle de maturité'!$B$2:$B$7, ""))} -> Une prise de conscience de l'existence de risques cyber pour l'organisation et une volonté de mettre en place des premières mesures cyber pertinentes. | K39: =IFERROR(__xludf.DUMMYFUNCTION("""COMPUTED_VALUE"""),"09 - SUPERVISER, AUDITER, RÉAGIR") -> 09 - SUPERVISER, AUDITER, RÉAGIR
B40: 37 | C40: Définir et appliquer une politique de sauvegarde des composants critiques | D40: Une politique de sauvegarde doit garantir la disponibilité des données, systèmes et logiciels en cas d’incident ou d’intrusion. Elle doit définir les modalités de sauvegarde, de stockage sécurisé et de restauration régulière des informations critiques. | E40: Voir règle | F40: Données, Logiciels, Systèmes d’exploitation, Infrastructures | G40: Politique de sauvegarde, liste des données et systèmes sauvegardés, configuration des outils de backup, procédures de restauration, preuves de tests de restauration, rapports d’exercices de reprise, règles de stockage et de rétention des sauvegardes | H40: 4 - Confirmé | I40: {=IF(H40="", "", XLOOKUP(H40, 'Echelle de maturité'!$C$2:$C$7, 'Echelle de maturité'!$B$2:$B$7, ""))} -> Une cartographie précise de ses risques cyber pour l'organisation, un plan d'action cyber approfondi et des moyens humains et budgétaires dédiés. | K40: =IFERROR(__xludf.DUMMYFUNCTION("""COMPUTED_VALUE"""),"09 - SUPERVISER, AUDITER, RÉAGIR") -> 09 - SUPERVISER, AUDITER, RÉAGIR
B41: 38 | C41: Procéder à des contrôles et audits de sécurité réguliers puis appliquer les actions correctives associées | D41: Des audits de sécurité doivent être réalisés régulièrement afin d’évaluer l’efficacité des mesures mises en place et détecter les écarts entre les règles et leur application. Les résultats doivent donner lieu à des plans d’actions suivis dans le temps. | E41: Voir règle | F41: Documentation, Systèmes d’information (globaux), Réseaux, Logiciels, Infrastructures | G41: Rapports d’audit internes ou externes, plan d’actions correctives, tableaux de suivi des actions, comptes rendus de revues périodiques, indicateurs de suivi (KPI sécurité), preuves de réalisation des corrections | H41: 3 - Intermédiaire | I41: {=IF(H41="", "", XLOOKUP(H41, 'Echelle de maturité'!$C$2:$C$7, 'Echelle de maturité'!$B$2:$B$7, ""))} -> Une conscience partagée des risques cyber pour l'organisation et la volonté de formaliser un plan d'action cyber complet tout en ajustant les moyens en conséquence. | K41: =IFERROR(__xludf.DUMMYFUNCTION("""COMPUTED_VALUE"""),"09 - SUPERVISER, AUDITER, RÉAGIR") -> 09 - SUPERVISER, AUDITER, RÉAGIR
B42: 39 | C42: Désigner un référent en sécurité des systèmes d’information et le faire connaître auprès du personnel | D42: Une entité doit désigner un référent SSI chargé de centraliser les questions, incidents et bonnes pratiques de sécurité. Ce référent assure la diffusion des règles et contribue à l’amélioration continue de la sécurité du système d’information. | E42: Voir règle | F42: Documentation, Systèmes d’information, Services | G42: Nomination officielle du référent SSI, description de rôle et responsabilités, procédures de traitement des incidents, supports de sensibilisation, plan de formation SSI, canaux de communication SSI internes | H42: 4 - Confirmé | I42: {=IF(H42="", "", XLOOKUP(H42, 'Echelle de maturité'!$C$2:$C$7, 'Echelle de maturité'!$B$2:$B$7, ""))} -> Une cartographie précise de ses risques cyber pour l'organisation, un plan d'action cyber approfondi et des moyens humains et budgétaires dédiés. | K42: =IFERROR(__xludf.DUMMYFUNCTION("""COMPUTED_VALUE"""),"09 - SUPERVISER, AUDITER, RÉAGIR") -> 09 - SUPERVISER, AUDITER, RÉAGIR
...

Sheet Dashboard guide de lANSSI

Sheet DORA
A2: Domaine | B2: ID Contrôle | C2: Exigence / contrôle | D2: Description simple | E2: Description complète | F2: Type d’actif | G2: Fonction sécurité | H2: Preuve attendue | I2: Niveau de maturité | J2: Description du niveau | K2: Risque encouru | L2: Commentaire | M2: Recommendation
A3: I. GESTION DES RISQUES TIC | B3: 1 | C3: Définir la responsabilité de la direction | D3: Impliquer activement la direction générale dans la sécurité de l'information, incluant la validation des budgets et l'endossement de la responsabilité des risques numériques. | E3: La direction doit porter la responsabilité finale de la gestion du risque TIC. Elle doit valider les politiques, approuver et revoir la stratégie de résilience numérique, les plans de continuité, les plans de réponse et de récupération, les audits TIC, les budgets et les dispositifs de suivi des prestataires TIC. | F3: Organisation | G3: Gouverner | H3: Procès-verbal, politique validée, responsabilités formalisées | I3: 5 - Optimal | J3: {=IFERROR(INDEX('Echelle de maturité'!$B$2:$B$7, MATCH(I3, 'Echelle de maturité'!$C$2:$C$7, 0)), "")} -> Des objectifs de réduction des risques cyber intégrés à la stratégie de l'organisation. Des moyens humains, budgétaires conséquents, un plan d'action cyber exhaustif, adapté aux menaces stratégiques. | K3: {=MAP(C3:C34, I3:I34, LAMBDA(exigence, niveau, IF(OR(niveau="1 - Insuffisant", niveau="2 - Émergent"), IFERROR(VLOOKUP(exigence, {"Définir la responsabilité de la direction","Absence de vision stratégique et de budget adéquat. En cas de crise, la responsabilité légale des dirigeants peut être engagée." ; "Définir les rôles et responsabilités TIC","Confusion dans les actions de sécurité et conflits d'intérêts. Risque d'inaction ou de mauvaise gestion lors d'un incident critique." ; "Mettre en place un cadre de gestion des risques TIC","Pilotage à l'aveugle de la sécurité. Les vulnérabilités majeures peuvent passer inaperçues jusqu'à l'exploitation par un attaquant." ; "Documenter les politiques, procédures et outils TIC","Perte de connaissance et pratiques hétérogènes. Difficulté à maintenir un niveau de sécurité constant et à prouver la conformité." ; "Réaliser des audits internes TIC","Sentiment de fausse sécurité. Les failles systémiques s'accumulent sans être détectées ni corrigées." ; "Définir une stratégie de résilience numérique","Incapacité à maintenir l'activité en cas de crise majeure. Risque de paralysie prolongée et de pertes financières massives." ; "Identifier les actifs informationnels et TIC","Impossibilité de protéger ce qu'on ne connaît pas. Des actifs critiques 'fantômes' peuvent servir de porte d'entrée aux attaquants." ; "Protéger les actifs TIC","Exposition directe aux cyberattaques. Risque élevé de compromission, de vol de données ou de destruction d'infrastructures." ; "Maintenir des systèmes TIC fiables et à jour","Exploitation facile de vulnérabilités connues par les cybercriminels. Risque d'intrusion automatisée via des failles non patchées." ; "Détecter les anomalies et incidents TIC","Les attaquants peuvent rester cachés longtemps dans le réseau. L'impact de l'attaque s'aggrave avec le temps de détection." ; "Mettre en place une politique de continuité TIC","Arrêt total des opérations en cas de sinistre. Incapacité à fournir les services essentiels aux clients." ; "Définir des plans de réponse et de récupération","Panique et désorganisation lors d'une cyberattaque. Les dommages s'amplifient par manque de réaction coordonnée." ; "Définir des sauvegardes et restaurations","Perte définitive de données critiques suite à un ransomware ou un sinistre. Impossibilité de relancer l'activité." ; "Mettre en place un processus de gestion des incidents TIC","Traitement inefficace des incidents. Les mêmes attaques peuvent se reproduire sans amélioration des défenses." ; "Classifier les incidents selon leur gravité","Gaspillage des ressources sur des incidents mineurs au détriment des crises réelles. Risque de mauvaise appréciation de l'impact." ; "Notifier les incidents TIC majeurs","Sanctions réglementaires sévères et amendes. Perte de confiance des autorités et des partenaires." ; "Conserver une trace des incidents TIC","Incapacité à tirer les leçons du passé. L'organisation reste vulnérable aux mêmes méthodes d'attaque." ; "Prévoir une stratégie de communication en cas d’incident TIC","Communication chaotique en temps de crise. Atteinte grave à la réputation et perte de confiance des clients." ; "Réaliser des tests de résilience basiques","Découverte des failles par les attaquants plutôt que par l'organisation. Augmentation de la surface d'attaque exploitable." ; "Réaliser des tests de pénétration fondés sur la menace (TLPT)","Illusion de sécurité face à des attaquants avancés. Les défenses ne sont pas éprouvées contre des scénarios réels complexes." ; "Corriger les faiblesses détectées lors des tests","Les vulnérabilités connues restent exploitables. Négligence coupable facilitant grandement le travail des cybercriminels." ; "Gérer les risques liés aux tiers TIC","Compromission de l'organisation via un partenaire moins sécurisé (attaque par rebond). Fuite de données confiées à des tiers." ; "Tenir un registre des contrats TIC","Perte de contrôle sur les prestataires et les données externalisées. Difficulté à évaluer l'exposition globale aux risques." ; "Évaluer les prestataires avant contrat","Intégration de partenaires vulnérables dans l'écosystème. Introduction de failles de sécurité dès le début de la relation." ; "Définir les exigences contractuelles","Aucun levier juridique pour imposer des mesures de sécurité. Impossibilité d'exiger des réparations en cas de défaillance du tiers." ; "Prévoir des droits d’audit et de contrôle","Confiance aveugle envers les prestataires. Impossibilité de vérifier la réalité des mesures de sécurité annoncées." ; "Prévoir une stratégie de sortie","Dépendance totale à un prestataire (vendor lock-in). Risque de paralysie si le partenaire fait faillite ou subit une attaque." ; "Participer au partage d'informations sur les menaces","Isolement face aux nouvelles menaces. L'organisation réagit avec retard par rapport au reste du secteur financier." ; "Réaliser des revues post-incident","Répétition des mêmes erreurs de gestion de crise. Aucune amélioration continue de la résilience." ; "Intégrer les leçons apprises","Stagnation du niveau de sécurité. L'organisation n'évolue pas au même rythme que les techniques d'attaque." ; "Former et sensibiliser le personnel","Les employés deviennent le maillon faible (phishing, ingénierie sociale). Augmentation des incidents liés à des erreurs humaines." ; "Suivre les évolutions technologiques et les cybermenaces","Obsolescence des mesures de défense. L'organisation devient une cible facile pour les nouvelles méthodes d'attaque."}, 2, FALSE), ""), "")))}
B4: 2 | C4: Définir les rôles et responsabilités TIC | D4: Définir clairement et formaliser les rôles et responsabilités de chaque collaborateur en matière de sécurité de l'information. | E4: Définir clairement les rôles et responsabilités liés aux fonctions TIC, à la sécurité, à la gestion des risques, au contrôle et à l’audit. L’organisation doit assurer une séparation suffisante entre les fonctions de gestion du risque TIC, les fonctions de contrôle et l’audit interne afin d’éviter les conflits d’intérêts. | F4: Organisation | G4: Gouverner | H4: Organigramme, fiches de rôles, matrice RACI | I4: 2 - Émergent | J4: {=IFERROR(INDEX('Echelle de maturité'!$B$2:$B$7, MATCH(I4, 'Echelle de maturité'!$C$2:$C$7, 0)), "")} -> Une prise de conscience de l'existence de risques cyber pour l'organisation et une volonté de mettre en place des premières mesures cyber pertinentes. | K4: Confusion dans les actions de sécurité et conflits d'intérêts. Risque d'inaction ou de mauvaise gestion lors d'un incident critique.
B5: 3 | C5: Mettre en place un cadre de gestion des risques TIC | D5: Structurer la démarche de sécurité via un cadre de référence documentant l'identification, l'évaluation et le traitement des risques TIC. | E5: Mettre en place un cadre de gestion des risques TIC solide, complet et documenté, intégré au dispositif global de gestion des risques. Ce cadre doit permettre d’identifier, de protéger, de détecter, de répondre, de récupérer et de suivre les risques liés aux technologies de l’information et de la communication. | F5: Organisation | G5: Gouverner | H5: Politique de gestion des risques TIC, procédure, registre des risques | I5: 4 - Confirmé | J5: {=IFERROR(INDEX('Echelle de maturité'!$B$2:$B$7, MATCH(I5, 'Echelle de maturité'!$C$2:$C$7, 0)), "")} -> Une cartographie précise de ses risques cyber pour l'organisation, un plan d'action cyber approfondi et des moyens humains et budgétaires dédiés.
B6: 4 | C6: Documenter les politiques, procédures et outils TIC | D6: Documenter, valider par la direction et mettre à jour régulièrement l'ensemble des politiques et procédures de sécurité de l'information. | E6: Documenter les stratégies, politiques, procédures, protocoles et outils TIC nécessaires à la gestion du risque TIC. Cette documentation doit être tenue à jour, revue régulièrement et permettre de démontrer la manière dont l’organisation protège ses actifs informationnels, ses systèmes, ses infrastructures et ses services critiques. | F6: Organisation | G6: Gouverner | H6: Politiques, procédures et stratégies documentées | I6: 4 - Confirmé | J6: {=IFERROR(INDEX('Echelle de maturité'!$B$2:$B$7, MATCH(I6, 'Echelle de maturité'!$C$2:$C$7, 0)), "")} -> Une cartographie précise de ses risques cyber pour l'organisation, un plan d'action cyber approfondi et des moyens humains et budgétaires dédiés.
B7: 5 | C7: Réaliser des audits internes TIC | D7: Réaliser régulièrement des audits internes ou externes indépendants pour vérifier l'application des règles de sécurité et identifier les axes d'amélioration. | E7: Soumettre régulièrement le cadre de gestion des risques TIC à des audits internes réalisés par des personnes disposant de compétences suffisantes en risque TIC et d’une indépendance appropriée. Les constats d’audit doivent donner lieu à un suivi formalisé et à la correction des points critiques identifiés. | F7: Processus | G7: Gouverner / Évaluer | H7: Rapports d'audit interne, plan d'action post-audit. | I7: 5 - Optimal | J7: {=IFERROR(INDEX('Echelle de maturité'!$B$2:$B$7, MATCH(I7, 'Echelle de maturité'!$C$2:$C$7, 0)), "")} -> Des objectifs de réduction des risques cyber intégrés à la stratégie de l'organisation. Des moyens humains, budgétaires conséquents, un plan d'action cyber exhaustif, adapté aux menaces stratégiques.
B8: 6 | C8: Définir une stratégie de résilience numérique | D8: Élaborer une stratégie de résilience numérique à long terme pour assurer la continuité des opérations en cas d'incident informatique majeur. | E8: Définir une stratégie de résilience opérationnelle numérique expliquant comment le cadre de gestion du risque TIC soutient les objectifs de l’organisation. Cette stratégie doit préciser la tolérance au risque TIC, les objectifs de sécurité, les mécanismes de détection et de protection, les tests de résilience et la stratégie de communication en cas d’incident. | F8: Organisation | G8: Gouverner | H8: Stratégie de résilience numérique documentée et approuvée | I8: 5 - Optimal | J8: {=IFERROR(INDEX('Echelle de maturité'!$B$2:$B$7, MATCH(I8, 'Echelle de maturité'!$C$2:$C$7, 0)), "")} -> Des objectifs de réduction des risques cyber intégrés à la stratégie de l'organisation. Des moyens humains, budgétaires conséquents, un plan d'action cyber exhaustif, adapté aux menaces stratégiques.
B9: 7 | C9: Identifier les actifs informationnels et TIC | D9: Réaliser un inventaire exhaustif et évaluer la criticité des actifs matériels, logiciels et des données sensibles. | E9: Identifier, classer et documenter les actifs informationnels et TIC nécessaires aux activités de l’organisation. Cela comprend notamment les données, logiciels, matériels, serveurs, infrastructures, locaux sensibles, services critiques, dépendances internes et externes, ainsi que leurs interconnexions. | F9: Matériel / Logiciel / Information | G9: Identifier | H9: Cartographie des actifs, registre des actifs | I9: 5 - Optimal | J9: {=IFERROR(INDEX('Echelle de maturité'!$B$2:$B$7, MATCH(I9, 'Echelle de maturité'!$C$2:$C$7, 0)), "")} -> Des objectifs de réduction des risques cyber intégrés à la stratégie de l'organisation. Des moyens humains, budgétaires conséquents, un plan d'action cyber exhaustif, adapté aux menaces stratégiques.
B10: 8 | C10: Protéger les actifs TIC | D10: Implémenter des mesures de protection techniques et organisationnelles (gestion des accès, mots de passe robustes, chiffrement) pour sécuriser les actifs. | E10: Protéger les actifs informationnels et TIC contre les risques, notamment les dommages, les accès non autorisés, les usages abusifs, les pertes d’intégrité, d’authenticité, de confidentialité ou de disponibilité. Les mesures doivent couvrir les accès, les systèmes, les données, les infrastructures et les composants physiques sensibles. | F10: Matériel / Logiciel / Information | G10: Protéger | H10: Politiques de sécurité, preuves de chiffrement, gestion des accès | I10: 4 - Confirmé | J10: {=IFERROR(INDEX('Echelle de maturité'!$B$2:$B$7, MATCH(I10, 'Echelle de maturité'!$C$2:$C$7, 0)), "")} -> Une cartographie précise de ses risques cyber pour l'organisation, un plan d'action cyber approfondi et des moyens humains et budgétaires dédiés.
